<?xml version="1.0" ?>
<!-- =================================================================================== -->
<!-- |    This document was autogenerated by xacro from /home/fasta/Projects/ROS/mobile_robot_ws/src/mobile_robot_description/urdf/mobile_robot.urdf.xacro | -->
<!-- |    EDITING THIS FILE BY HAND IS NOT RECOMMENDED                                 | -->
<!-- =================================================================================== -->
<robot name="mobile_robot">
  <material name="red">
    <color rgba="1 0 0 1"/>
  </material>
  <material name="green">
    <color rgba="0 1 0 1"/>
  </material>
  <material name="blue">
    <color rgba="0 0 1 1"/>
  </material>
  <material name="gray">
    <color rgba="0.8 0.8 0.8 1"/>
  </material>
  <material name="dark_gray">
    <color rgba="0.3 0.3 0.3 1"/>
  </material>
  <material name="chassis_grey">
    <color rgba="0.5 0.5 0.5 1.0"/>
  </material>
  <material name="wheel_grey">
    <color rgba="0.5 0.5 0.5 1.0"/>
  </material>
  <!-- <xacro:include filename="mobile_base_1.urdf.xacro" />
    <xacro:include filename="camera_1.urdf.xacro" />
    <xacro:include filename="depth_camera_1.urdf.xacro" />
    <xacro:include filename="imu_1.urdf.xacro" />
    <xacro:include filename="lidar_1.urdf.xacro" /> -->
  <link name="base_footprint"/>
  <joint name="base_footprint_joint" type="fixed">
    <parent link="base_footprint"/>
    <child link="base_link"/>
    <origin rpy="0 0 0" xyz="0 0 0.05"/>
  </joint>
  <link name="base_link">
    <visual>
      <origin rpy="1.5708 0.0 3.1416" xyz="3.2 -0.32 0.0"/>
      <geometry>
        <mesh filename="/home/fasta/Projects/Genesis/meshes/chasis.STL" scale="0.001 0.001 0.001"/>
      </geometry>
      <material name="chassis_grey"/>
    </visual>
    <collision>
      <!-- <origin xyz="3.2 -0.32 0.0" rpy="1.5708 0.0 3.1416"/> -->
      <origin rpy="0.0 0.0 0.0" xyz="0.0 0.01 0.14"/>
      <geometry>
        <!-- <mesh filename="package://mobile_robot_description/meshes/chasis.STL" scale="0.001 0.001 0.001"/> -->
        <box size="0.9 0.67 0.27"/>
      </geometry>
    </collision>
    <inertial>
      <mass value="20.0"/>
      <origin rpy="0 0 0" xyz="0 0 0.1325"/>
      <inertia ixx="1.0" ixy="0" ixz="0" iyy="1.5" iyz="0" izz="2.0"/>
    </inertial>
  </link>
  <joint name="base_left_wheel_joint" type="continuous">
    <parent link="base_link"/>
    <child link="left_wheel_link"/>
    <origin rpy="0 0 0" xyz="0.0 0.23 0.05"/>
    <axis xyz="0 1 0"/>
  </joint>
  <link name="left_wheel_link">
    <visual>
      <origin rpy="1.5708 0 3.1416" xyz="0.1 -0.02 -0.1"/>
      <geometry>
        <mesh filename="/home/fasta/Projects/Genesis/meshes/wheel.STL" scale="0.001 0.001 0.001"/>
      </geometry>
      <material name="wheel_grey"/>
    </visual>
    <collision>
      <!-- <origin xyz="0.1 -0.02 -0.1" rpy="1.5708 0 3.1416"/> -->
      <origin rpy="0.0 0.0 0.0" xyz="0.0 0.0 0.0"/>
      <geometry>
        <!-- <mesh filename="package://mobile_robot_description/meshes/wheel.STL" scale="0.001 0.001 0.001"/> -->
        <sphere radius="0.1"/>
      </geometry>
    </collision>
    <inertial>
      <mass value="2.0"/>
      <origin rpy="0 0 0" xyz="0 0 0"/>
      <inertia ixx="0.01" ixy="0" ixz="0" iyy="0.01" iyz="0" izz="0.02"/>
    </inertial>
  </link>
  <joint name="base_right_wheel_joint" type="continuous">
    <parent link="base_link"/>
    <child link="right_wheel_link"/>
    <origin rpy="0 0 0" xyz="0.0 -0.23 0.05"/>
    <axis xyz="0 1 0"/>
  </joint>
  <link name="right_wheel_link">
    <visual>
      <origin rpy="1.5708 0 3.1416" xyz="0.1 -0.02 -0.1"/>
      <geometry>
        <mesh filename="/home/fasta/Projects/Genesis/meshes/wheel.STL" scale="0.001 0.001 0.001"/>
      </geometry>
      <material name="wheel_grey"/>
    </visual>
    <collision>
      <!-- <origin xyz="0.1 -0.02 -0.1" rpy="1.5708 0 3.1416"/> -->
      <origin rpy="0.0 0.0 0.0" xyz="0.0 0.0 0.0"/>
      <geometry>
        <!-- <mesh filename="package://mobile_robot_description/meshes/wheel.STL" scale="0.001 0.001 0.001"/> -->
        <sphere radius="0.1"/>
      </geometry>
    </collision>
    <inertial>
      <mass value="2.0"/>
      <origin rpy="0 0 0" xyz="0 0 0"/>
      <inertia ixx="0.01" ixy="0" ixz="0" iyy="0.01" iyz="0" izz="0.02"/>
    </inertial>
  </link>
  <joint name="base_rear_left_caster_wheel_joint" type="fixed">
    <parent link="base_link"/>
    <child link="rear_left_caster_wheel"/>
    <origin rpy="0 0 0" xyz="-0.3 0.2 0.0105"/>
  </joint>
  <link name="rear_left_caster_wheel">
    <visual>
      <geometry>
        <sphere radius="0.06"/>
      </geometry>
      <material name="gray"/>
      <origin rpy="0 0 0" xyz="0 0 0"/>
    </visual>
    <collision>
      <geometry>
        <sphere radius="0.06"/>
      </geometry>
      <origin rpy="0 0 0" xyz="0 0 0"/>
    </collision>
    <inertial>
      <mass value="0.25"/>
      <origin rpy="0 0 0" xyz="0 0 0"/>
      <inertia ixx="0.00036" ixy="0" ixz="0" iyy="0.00036" iyz="0" izz="0.00036"/>
    </inertial>
  </link>
  <joint name="base_rear_right_caster_wheel_joint" type="fixed">
    <parent link="base_link"/>
    <child link="rear_right_caster_wheel"/>
    <origin rpy="0 0 0" xyz="-0.3 -0.2 0.0105"/>
  </joint>
  <link name="rear_right_caster_wheel">
    <visual>
      <geometry>
        <sphere radius="0.06"/>
      </geometry>
      <material name="gray"/>
      <origin rpy="0 0 0" xyz="0 0 0"/>
    </visual>
    <collision>
      <geometry>
        <sphere radius="0.06"/>
      </geometry>
      <origin rpy="0 0 0" xyz="0 0 0"/>
    </collision>
    <inertial>
      <mass value="0.25"/>
      <origin rpy="0 0 0" xyz="0 0 0"/>
      <inertia ixx="0.00036" ixy="0" ixz="0" iyy="0.00036" iyz="0" izz="0.00036"/>
    </inertial>
  </link>
  <joint name="base_front_left_caster_wheel_joint" type="fixed">
    <parent link="base_link"/>
    <child link="front_left_caster_wheel"/>
    <origin rpy="0 0 0" xyz="0.3 0.2 0.0105"/>
  </joint>
  <link name="front_left_caster_wheel">
    <visual>
      <geometry>
        <sphere radius="0.06"/>
      </geometry>
      <material name="gray"/>
      <origin rpy="0 0 0" xyz="0 0 0"/>
    </visual>
    <collision>
      <geometry>
        <sphere radius="0.06"/>
      </geometry>
      <origin rpy="0 0 0" xyz="0 0 0"/>
    </collision>
    <inertial>
      <mass value="0.25"/>
      <origin rpy="0 0 0" xyz="0 0 0"/>
      <inertia ixx="0.00036" ixy="0" ixz="0" iyy="0.00036" iyz="0" izz="0.00036"/>
    </inertial>
  </link>
  <joint name="base_front_right_caster_wheel_joint" type="fixed">
    <parent link="base_link"/>
    <child link="front_right_caster_wheel"/>
    <origin rpy="0 0 0" xyz="0.3 -0.2 0.0105"/>
  </joint>
  <link name="front_right_caster_wheel">
    <visual>
      <geometry>
        <sphere radius="0.06"/>
      </geometry>
      <material name="gray"/>
      <origin rpy="0 0 0" xyz="0 0 0"/>
    </visual>
    <collision>
      <geometry>
        <sphere radius="0.06"/>
      </geometry>
      <origin rpy="0 0 0" xyz="0 0 0"/>
    </collision>
    <inertial>
      <mass value="0.25"/>
      <origin rpy="0 0 0" xyz="0 0 0"/>
      <inertia ixx="0.00036" ixy="0" ixz="0" iyy="0.00036" iyz="0" izz="0.00036"/>
    </inertial>
  </link>
  <joint name="base_zed_camera_joint" type="fixed">
    <parent link="base_link"/>
    <child link="zed_camera_link"/>
    <origin rpy="0 0 0" xyz="0.4 0.03 0.11"/>
  </joint>
  <link name="zed_camera_link">
    <visual>
      <origin rpy="0 0 1.5708" xyz="0 -0.1 0"/>
      <geometry>
        <mesh filename="/home/fasta/Projects/Genesis/meshes/zed.STL" scale="0.001 0.001 0.001"/>
      </geometry>
      <material name="Gray">
        <color rgba="0.5 0.5 0.5 1.0"/>
      </material>
    </visual>
    <!-- <collision>
            <origin xyz="0 -0.1 0" rpy="0 0 1.5708"/>
            <geometry>
                <mesh filename="package://mobile_robot_description/meshes/zed.STL" scale="0.001 0.001 0.001"/>
            </geometry>
        </collision> -->
  </link>
  <joint name="zed_camera_optical_joint" type="fixed">
    <parent link="zed_camera_link"/>
    <child link="zed_left_optical_frame"/>
    <origin rpy="-1.5708 0 -1.5708" xyz="0.0 0.05 0.02"/>
  </joint>
  <link name="zed_left_optical_frame">
    <inertial>
      <mass value="0.1"/>
      <origin rpy="0 0 0" xyz="0 0 0"/>
      <inertia ixx="1e-5" ixy="0" ixz="0" iyy="1e-5" iyz="0" izz="1e-5"/>
    </inertial>
    <visual>
      <origin rpy="0 0 0" xyz="0 0 0"/>
      <geometry>
        <sphere radius="0.01"/>
      </geometry>
      <material name="camera_frame">
        <color rgba="0.0 1.0 0.0 1.0"/>
      </material>
    </visual>
    <!-- <collision>
            <origin xyz="0 0 0" rpy="0 0 0"/>
            <geometry>
                <sphere radius="0.01"/>
            </geometry>
        </collision> -->
  </link>
  <joint name="zed_camera_right_optical_joint" type="fixed">
    <parent link="zed_camera_link"/>
    <child link="zed_right_optical_frame"/>
    <origin rpy="-1.5708 3.1416 -1.5708" xyz="0 -0.05 0.02"/>
  </joint>
  <link name="zed_right_optical_frame">
    <inertial>
      <mass value="0.1"/>
      <origin rpy="0 0 0" xyz="0 0 0"/>
      <inertia ixx="1e-5" ixy="0" ixz="0" iyy="1e-5" iyz="0" izz="1e-5"/>
    </inertial>
    <visual>
      <origin rpy="0 0 0" xyz="0 0 0"/>
      <geometry>
        <sphere radius="0.01"/>
      </geometry>
      <material name="camera_frame">
        <color rgba="0.0 0.0 1.0 1.0"/>
      </material>
    </visual>
    <!-- <collision>
            <origin xyz="0 0 0" rpy="0 0 0"/>
            <geometry>
                <sphere radius="0.01"/>
            </geometry>
        </collision> -->
  </link>
  <gazebo>
    <plugin filename="gz-sim-sensors-system" name="gz::sim::systems::Sensors">
      <render_engine>ogre2</render_engine>
    </plugin>
  </gazebo>
  <gazebo reference="zed_camera_link">
    <sensor name="camera" type="camera">
      <camera>
        <horizontal_fov>1.3962634</horizontal_fov>
        <image>
          <width>640</width>
          <height>480</height>
          <format>R8G8B8</format>
        </image>
        <clip>
          <near>0.1</near>
          <far>100</far>
        </clip>
        <noise>
          <type>gaussian</type>
          <mean>0.0</mean>
          <stddev>0.007</stddev>
        </noise>
        <camera_info_topic>camera/camera_info</camera_info_topic>
        <optical_fram_id>zed_left_optical_frame</optical_fram_id>
      </camera>
      <frame_id>zed_left_optical_frame</frame_id>
      <always_on>1</always_on>
      <update_rate>30</update_rate>
      <visualize>true</visualize>
      <topic>camera/image_raw</topic>
    </sensor>
    <sensor name="depth_camera" type="depth_camera">
      <depth_camera>
        <horizontal_fov>1.3962634</horizontal_fov>
        <camera_info>
          <width>320</width>
          <height>240</height>
          <K>700 0 960 0 700 540 0 0 1</K>
          <D>0 0 0 0 0</D>
          <distortion_model>plumb_bob</distortion_model>
        </camera_info>
        <clip>
          <near>0.1</near>
          <far>100</far>
        </clip>
        <noise>
          <type>gaussian</type>
          <mean>0.0</mean>
          <stddev>0.007</stddev>
        </noise>
        <optical_fram_id>zed_right_optical_frame</optical_fram_id>
      </depth_camera>
      <frame_id>depth_camera</frame_id>
      <always_on>1</always_on>
      <update_rate>30</update_rate>
      <visualize>true</visualize>
      <topic>depth_camera</topic>
    </sensor>
  </gazebo>
  <link name="zed_imu_link">
    <inertial>
      <mass value="0.05"/>
      <origin rpy="0 0 0" xyz="0 0 0"/>
      <inertia ixx="1e-5" ixy="0" ixz="0" iyy="1e-5" iyz="0" izz="1e-5"/>
    </inertial>
    <visual>
      <origin rpy="0 0 0" xyz="0 0 0"/>
      <geometry>
        <box size="0.02 0.02 0.02"/>
      </geometry>
      <material name="imu_frame">
        <color rgba="1.0 1.0 0.0 1.0"/>
      </material>
    </visual>
    <!-- <collision>
            <origin xyz="0 0 0" rpy="0 0 0"/>
            <geometry>
                <box size="0.02 0.02 0.02"/>
            </geometry>
        </collision> -->
  </link>
  <joint name="zed_imu_joint" type="fixed">
    <parent link="zed_camera_link"/>
    <child link="zed_imu_link"/>
    <origin rpy="0 0 0" xyz="0 0 0.02"/>
  </joint>
  <gazebo>
    <plugin filename="gz-sim-imu-system" name="gz::sim::systems::Imu"/>
  </gazebo>
  <gazebo reference="zed_imu_link">
    <sensor name="imu" type="imu">
      <imu/>
      <always_on>1</always_on>
      <initialOrientationAsReference>false</initialOrientationAsReference>
      <updateRate>100</updateRate>
      <visualize>true</visualize>
      <topic>imu/data_raw</topic>
    </sensor>
  </gazebo>
  <joint name="top_lidar_joint" type="fixed">
    <parent link="base_link"/>
    <child link="lidar_link"/>
    <origin rpy="0.0 0.0 0.0" xyz="0.0 0.0 0.27"/>
  </joint>
  <link name="lidar_link">
    <visual>
      <origin rpy="0.0 0.0 0.0" xyz="0.0 0.0 0.0"/>
      <geometry>
        <cylinder length="0.03" radius="0.05"/>
      </geometry>
      <material name="red"/>
    </visual>
    <collision>
      <origin rpy="0.0 0.0 0.0" xyz="0.0 0.0 0.0"/>
      <geometry>
        <cylinder length="0.03" radius="0.05"/>
      </geometry>
    </collision>
    <inertial>
      <mass value="0.03"/>
      <origin rpy="0 0 0" xyz="0 0 0"/>
      <inertia ixx="2.1000000000000002e-05" ixy="0" ixz="0" iyy="2.1000000000000002e-05" iyz="0" izz="3.7500000000000003e-05"/>
    </inertial>
  </link>
  <gazebo reference="lidar_link">
    <sensor name="gpu_lidar" type="gpu_lidar">
      <!-- <sensor type="ray" name="lidar"> -->
      <pose relative_to="lidar_link">0 0 0 0 0 0</pose>
      <always_on>1</always_on>
      <visualize>true</visualize>
      <update_rate>30</update_rate>
      <topic>lidar/pointcloud</topic>
      <lidar>
        <scan>
          <horizontal>
            <samples>720</samples>
            <resolution>1</resolution>
            <min_angle>-3.14</min_angle>
            <max_angle>3.14</max_angle>
          </horizontal>
          <vertical>
            <samples>32</samples>
            <resolution>1</resolution>
            <min_angle>-0.5</min_angle>
            <max_angle>0.5</max_angle>
          </vertical>
        </scan>
        <range>
          <min>0.8</min>
          <max>20.0</max>
          <resolution>0.001</resolution>
        </range>
        <noise>
          <type>gaussian</type>
          <mean>0.0</mean>
          <stddev>0.007</stddev>
        </noise>
      </lidar>
    </sensor>
  </gazebo>
  <gazebo reference="rear_left_caster_wheel">
    <mu1 value="0.1"/>
    <mu2 value="0.1"/>
  </gazebo>
  <gazebo reference="rear_right_caster_wheel">
    <mu1 value="0.1"/>
    <mu2 value="0.1"/>
  </gazebo>
  <gazebo reference="front_left_caster_wheel">
    <mu1 value="0.1"/>
    <mu2 value="0.1"/>
  </gazebo>
  <gazebo reference="front_right_caster_wheel">
    <mu1 value="0.1"/>
    <mu2 value="0.1"/>
  </gazebo>
  <!-- <gazebo>
            <plugin filename="gz-sim-diff-drive-system" name="gz::sim::systems::DiffDrive">
                <left_joint>base_left_wheel_joint</left_joint>
                <right_joint>base_right_wheel_joint</right_joint>
                <wheel_separation>${base_width - (wheel_length + epsilon)}</wheel_separation>
                <wheel_radius>${wheel_radius}</wheel_radius>
                <odom_publish_frequency>50</odom_publish_frequency>
                <frame_id>odom</frame_id>
                <child_frame_id>base_footprint</child_frame_id>
                <topic>/cmd_vel</topic>
                <odom_topic>/odometry</odom_topic>
                <tf_topic>/tf</tf_topic>
            </plugin>
        </gazebo> -->
  <!-- <gazebo>
            <plugin filename="gz-sim-joint-state-publisher-system" name="gz::sim::systems::JointStatePublisher">
                <joint_name>base_left_wheel_joint</joint_name>
                <joint_name>base_right_wheel_joint</joint_name>
                <topic>/joint_states</topic>
            </plugin>
        </gazebo> -->
  <gazebo>
    <plugin filename="gz_ros2_control-system" name="gz_ros2_control::GazeboSimROS2ControlPlugin">
      <parameters>/home/fasta/Projects/ROS/mobile_robot_ws/install/mobile_robot_controller/share/mobile_robot_controller/config/mobile_robot_controllers.yaml</parameters>
      <controller_manager_node_name>controller_manager</controller_manager_node_name>
      <ros>
        <remapping>/diff_drive_base_controller/cmd_vel:=/cmd_vel</remapping>
        <remapping>/diff_drive_base_controller/odom:=/odom</remapping>
      </ros>
    </plugin>
  </gazebo>
  <ros2_control name="MobileRobotVelocityHardwareSystem" type="system">
    <hardware>
      <plugin>gz_ros2_control/GazeboSimSystem</plugin>
    </hardware>
    <joint name="base_left_wheel_joint">
      <command_interface name="velocity">
        <param name="min">-2</param>
        <param name="max">+2</param>
      </command_interface>
      <state_interface name="position"/>
      <state_interface name="velocity"/>
    </joint>
    <joint name="base_right_wheel_joint">
      <command_interface name="velocity">
        <param name="min">-2</param>
        <param name="max">+2</param>
      </command_interface>
      <state_interface name="position"/>
      <state_interface name="velocity"/>
    </joint>
  </ros2_control>
</robot>
